<?xml version="1.0"?>

<robot name="aster" xmlns:xacro="http://www.ros.org/wiki/xacro">

	<material name="blue">
		<color rgba="0 0.0 1.0 1.0"/>
	</material>
	
	<link name="map">
	</link>
	
	<link name="chassis">
	<!-->
		<inertial>
			<mass value="0.906"/>
			<origin xyz="0.193 0.0 0.080" rpy="0 0 0"/>
			<inertia ixx="5.840e-3" ixy="0.0" ixz="1.724e-5" iyy="1.664e-2" iyz="0.0" izz="1.961e-2"/>			
		</inertial>
	<!-->
		<collision name="collision">
			<origin xyz="0.2 0 0.1" rpy="0 0 0"/>
			<geometry>
				<box size="0.4 0.2 0.1"/>
			</geometry>
			<material name="blue"/>
		</collision>
		<collision name="caster_collision">
			<origin xyz="0.075 0.0 0.050"/>
			<geometry>
				<sphere radius="0.05"/>
			</geometry>
			<material name="blue"/>
		</collision>		
		<visual name="visual">
			<origin xyz="0.2 0 0.1" rpy="0 0 0"/>
			<geometry>
				<box size="0.4 0.2 0.1"/>
			</geometry>

			<material name="blue"/>
		</visual>
		<visual name="caster_visual">
			<origin xyz="0.075 0.0 0.050"/>
			<geometry>
				<sphere radius="0.05"/>
			</geometry>
			<material name="blue"/>
		</visual>

	</link>
	
	<link name="right_wheel">
	<!-->	
		<inertial>
			<mass value="0.327"/>
			<origin rpy="1.5707 0 0" xyz="0.325 -0.125 0.050"/>
			<inertia ixx="2.478e-4" ixy="0.0" ixz="0.0" iyy="4.084e-4" iyz="0.0" izz="2.478e-4"/>			
		</inertial>
	<!-->
		<visual name="visual">
			<origin rpy="1.5707 0 0" xyz="0 0 0"/>
			<geometry>
				<cylinder length="0.04" radius="0.05"/>
			</geometry>
		</visual>
		<collision name="collision">
			<origin rpy="1.5707 0 0" xyz="0 0 0"/>
			<geometry>
				<cylinder length="0.04" radius="0.05"/>
			</geometry>
		</collision>
	</link>

	<link name="left_wheel">
	<!-->
		<inertial>
			<mass value="0.327"/>
			<origin rpy="1.5707 0 0" xyz="0.325 0.125 0.050"/>
			<inertia ixx="2.478e-4" ixy="0.0" ixz="0.0" iyy="4.084e-4" iyz="0.0" izz="2.478e-4"/>			
		</inertial>
	<!-->
		<visual name="visual">
			<origin rpy="1.5707 0 0" xyz="0 0 0"/>
			<geometry>
				<cylinder length="0.04" radius="0.05"/>
			</geometry>
		</visual>
		<collision name="collision">
			<origin rpy="1.5707 0 0" xyz="0 0 0"/>
			<geometry>
				<cylinder length="0.04" radius=	"0.05"/>
			</geometry>
		</collision>
	</link>
	
	<joint name="dummy_joint" type="fixed">
		<parent link="map"/>
		<child link="chassis"/>
	</joint>
	
	<joint name="right_wheel_joint" type="continuous">
		<parent link="chassis"/>
		<child link="right_wheel"/>
		<axis xyz="0 1 0"/>
		<origin xyz="0.325 -0.125 0.050"/>
	</joint>

	<joint name="left_wheel_joint" type="continuous">
		<parent link="chassis"/>
		<child link="left_wheel"/>
		<axis xyz="0 1 0"/>
		<origin xyz="0.325 0.125 0.050"/>	
	</joint>	
</robot>
