<?xml version="1.0"?>

<robot>
<macro name="wheel" params="name">
	<link name="${name}">
		<inertial>
			<mass value="0.327"/>
			<origin rpy="0 1.5707 0" xyz="0 0 0"/>
			<inertia ixx="2.478e-4" ixy="0.0" ixz="0.0" iyy="4.084e-4" iyz="0.0" izz="2.478e-4"/>			
		</inertial>
		<visual>
			<origin rpy="1.5707 0 0" xyz="0 0 0"/>
			<geometry>
				<cylinder length="0.04" radius="0.05"/>
			</geometry>
		</visual>
		<collision name="$collision_{name">
			<origin rpy="1.5707 0 0" xyz="0 0 0"/>
			<geometry>
				<cylinder length="0.04" radius="0.05"/>
			</geometry>
		</collision>
	</link>
</macro>
<macro name="wheel_joint" params="name child origin_xyz">
	<joint name="${name}" type="continuous">
		<origin rpy="0 0 0" xyz="${origin_xyz}"/>	
		<parent link="chassis"/>
		<child link="${child}"/>
		<axis xyz="0 1 0" rpy="0 0 0"/>
		<joint_properties damping="1.0" friction="1.0"/>
		<limit effort="1000" velocity="1000"/>
	</joint>
</macro>
</robot>
